<?xml version="1.0" encoding="utf-8"?>
<qroot>
<question>
<Title>Getting a 404 when trying to access a url python/django</Title>
<Body>&lt;p&gt;Currently getting a 404 error for my application when I try to access the url /contato, and I am not sure why, can anyone help me?&lt;/p&gt;&lt;p&gt;Here is the error:&lt;/p&gt;&lt;pre&gt;&lt;code&gt;Page not found (404)Request Method: GETRequest URL:    http://localhost:8002/contato(...)^contato/(...)&lt;/code&gt;&lt;/pre&gt;&lt;p&gt;Here is my code.&lt;/p&gt;&lt;p&gt;My main urls.py has:&lt;/p&gt;&lt;pre&gt;&lt;code&gt;from django.conf.urls import patterns, include, urlfrom django.conf import settingsfrom django.contrib import adminurlpatterns = patterns(&#x27;&#x27;,    url(r&#x27;^admin/password_reset/$&#x27;, &#x27;django.contrib.auth.views.password_reset&#x27;, name=&#x27;admin_password_reset&#x27;),    url(r&#x27;^admin/password_reset/done/$&#x27;, &#x27;django.contrib.auth.views.password_reset_done&#x27;),    url(r&#x27;^reset/(?P&amp;lt;uidb36&amp;gt;[0-9A-Za-z]+)-(?P&amp;lt;token&amp;gt;.+)/$&#x27;, &#x27;django.contrib.auth.views.password_reset_confirm&#x27;),    url(r&#x27;^reset/done/$&#x27;, &#x27;django.contrib.auth.views.password_reset_complete&#x27;),    url(r&#x27;^admin/&#x27;, include(admin.site.urls)),    url(r&#x27;^perfil/&#x27;, include(&#x27;perfil.urls&#x27;)),    url(r&#x27;^contato/&#x27;, include(&#x27;contato.urls&#x27;)),    url(r&#x27;^$&#x27;, &#x27;views.index&#x27;, name=&#x27;index&#x27;),)&lt;/code&gt;&lt;/pre&gt;&lt;p&gt;My contato.urls.py:&lt;/p&gt;&lt;pre&gt;&lt;code&gt;from django.conf.urls.defaults import patterns, urlurlpatterns = patterns(&#x27;contato.views&#x27;,    url(r&#x27;^contato/$&#x27;, &#x27;contato&#x27;, name=&quot;contato&quot;),)&lt;/code&gt;&lt;/pre&gt;&lt;p&gt;my views.py in contato:&lt;/p&gt;&lt;pre&gt;&lt;code&gt;from django.shortcuts import render_to_responsefrom django.template import RequestContextdef contato(request):render_to_response(&#x27;contato/contato.html&#x27;,locals(),context_instance=RequestContext(request),)&lt;/code&gt;&lt;/pre&gt;</Body>
<Tags>python,django,url,http-status-code-404</Tags>
</question>
<answer>
<Body>&lt;p&gt;You don&#x27;t have a match for the url &quot;/contato&quot;. In your base urls.py, you point the prefix &quot;/contato&quot; to include contato.urls, and then in that file you have a single URL which is again &quot;/contato&quot;: so the combined URL for that view is &quot;/contato/contato&quot;.&lt;/p&gt;&lt;p&gt;If you just want the URL to match &quot;contato&quot;, you should either get the included url to match just &quot;^$&quot;, or (probably better) don&#x27;t bother including the separate urls.py and match the view directly from the base file.&lt;/p&gt;</Body>
</answer>
</qroot>
