<?xml version="1.0" encoding="utf-8"?>
<qroot>
<question>
<Title>list out of range error when python-docx reads a table of which the border&#x27;s not aligned</Title>
<Body>&lt;p&gt;I am parsing a table (which looks like the image below) in Word docx file by using python-docx. But when it reads the table below it throws an error.I&#x27;ve noticed that there is a tiny &quot;crack&quot; at the right-end border of the table as I circled red in the picture. If I manually align the right-end border, my code will be fine. But isn&#x27;t there a clever way to solve it?&lt;/p&gt;&lt;pre&gt;&lt;code&gt;from docx import Documentdocument = Document(u&#x27;D:\\1.docx&#x27;)tables = document.tablesprint(tables[0].rows[0].cells[0].text)&lt;/code&gt;&lt;/pre&gt;&lt;p&gt;&lt;a href=&quot;https://i.stack.imgur.com/TCyhM.png&quot; rel=&quot;nofollow noreferrer&quot;&gt;&lt;img src=&quot;https://i.stack.imgur.com/TCyhM.png&quot; alt=&quot;table in my docx file&quot;&gt;&lt;/a&gt;&lt;/p&gt;&lt;p&gt;The error is:&lt;/p&gt;&lt;pre class=&quot;lang-none prettyprint-override&quot;&gt;&lt;code&gt;Traceback (most recent call last):  File &quot;C:\Users\lenovo\Anaconda2\envs\py3\lib\site-packages\IPython\core\interactiveshell.py&quot;, line 2862, in run_code    exec(code_obj, self.user_global_ns, self.user_ns)  File &quot;&amp;lt;ipython-input-168-61cbbaa7e1a8&amp;gt;&quot;, line 1, in &amp;lt;module&amp;gt;    tables[0].rows[0].cells[0].text  File &quot;C:\Users\lenovo\Anaconda2\envs\py3\lib\site-packages\docx\table.py&quot;, line 384, in cells    return tuple(self.table.row_cells(self._index))  File &quot;C:\Users\lenovo\Anaconda2\envs\py3\lib\site-packages\docx\table.py&quot;, line 106, in row_cells    return self._cells[start:end]  File &quot;C:\Users\lenovo\Anaconda2\envs\py3\lib\site-packages\docx\table.py&quot;, line 173, in _cells    cells.append(cells[-col_count])IndexError: list index out of rangeDuring handling of the above exception, another exception occurred:Traceback (most recent call last):  File &quot;C:\Users\lenovo\Anaconda2\envs\py3\lib\site-packages\IPython\core\interactiveshell.py&quot;, line 2808, in run_ast_nodes    if self.run_code(code, result):  File &quot;C:\Users\lenovo\Anaconda2\envs\py3\lib\site-packages\IPython\core\interactiveshell.py&quot;, line 2879, in run_code    self.showtraceback(running_compiled_code=True)TypeError: showtraceback() got an unexpected keyword argument &#x27;running_compiled_code&#x27;&lt;/code&gt;&lt;/pre&gt;&lt;p&gt;Can someone help me?&lt;/p&gt;</Body>
<Tags>python,python-docx</Tags>
</question>
</qroot>
